2017-05-18 11:04:03,354 [ERROR] django.request: Internal Server Error: /send_mails/
Traceback (most recent call last):
  File "/usr/local/lib/python2.7/dist-packages/django/core/handlers/base.py", line 149, in get_response
    response = self.process_exception_by_middleware(e, request)
  File "/usr/local/lib/python2.7/dist-packages/django/core/handlers/base.py", line 147, in get_response
    response = wrapped_callback(request, *callback_args, **callback_kwargs)
  File "/usr/local/lib/python2.7/dist-packages/django/views/decorators/csrf.py", line 58, in wrapped_view
    return view_func(*args, **kwargs)
  File "./domain/views.py", line 654, in send_mails
    connection.open()
  File "/usr/local/lib/python2.7/dist-packages/django/core/mail/backends/smtp.py", line 58, in open
    self.connection = connection_class(self.host, self.port, **connection_params)
  File "/usr/lib/python2.7/smtplib.py", line 256, in __init__
    (code, msg) = self.connect(host, port)
  File "/usr/lib/python2.7/smtplib.py", line 316, in connect
    self.sock = self._get_socket(host, port, self.timeout)
  File "/usr/lib/python2.7/smtplib.py", line 291, in _get_socket
    return socket.create_connection((host, port), timeout)
  File "/usr/lib/python2.7/socket.py", line 575, in create_connection
    raise err
error: [Errno 110] Connection timed out
